<?xml version="1.0" ?>
<!-- =================================================================================== -->
<!-- |    This document was autogenerated by xacro from sda10f_milling.xacro           | -->
<!-- |    EDITING THIS FILE BY HAND IS NOT RECOMMENDED                                 | -->
<!-- =================================================================================== -->
<robot name="sda10f_milling">
  <!-- link list -->
  <link name="torso_base_link">
    <visual>
      <geometry>
        <mesh filename="package://motoman_sda10f_support/meshes/sda10f/visual/base.stl"/>
      </geometry>
      <material name="">
        <color rgba="0.12941176470588237 0.14901960784313725 0.7490196078431373 1.0"/>
      </material>
    </visual>
    <collision>
      <geometry>
        <mesh filename="package://motoman_sda10f_support/meshes/sda10f/collision/base.stl"/>
      </geometry>
    </collision>
  </link>
  <link name="torso_link_b1">
    <visual>
      <origin rpy="0 0 0" xyz="0 0 0"/>
      <geometry>
        <mesh filename="package://motoman_sda10f_support/meshes/sda10f/visual/link_b1.stl"/>
      </geometry>
      <material name="">
        <color rgba="0.99 0.99 0.99 1"/>
      </material>
    </visual>
    <collision>
      <origin rpy="0 0 0" xyz="0 0 0"/>
      <geometry>
        <mesh filename="package://motoman_sda10f_support/meshes/sda10f/collision/link_b1.stl"/>
      </geometry>
    </collision>
  </link>
  <link name="torso_link_b2"/>
  <!-- joint list -->
  <joint name="torso_joint_b1" type="revolute">
    <parent link="torso_base_link"/>
    <child link="torso_link_b1"/>
    <origin rpy="0 0 0" xyz="0 0 0"/>
    <axis xyz="0 0 1"/>
    <limit effort="100" lower="-2.9670597283903604" upper="2.9670597283903604" velocity="2.2689280275926285"/>
  </joint>
  <joint name="torso_joint_b2" type="revolute">
    <parent link="torso_base_link"/>
    <child link="torso_link_b2"/>
    <origin rpy="0 0 0" xyz="0 0 0"/>
    <axis xyz="0 0 1"/>
    <limit effort="100" lower="-2.9670597283903604" upper="2.9670597283903604" velocity="2.2689280275926285"/>
    <mimic joint="torso_joint_b1" multiplier="1" offset="0"/>
  </joint>
  <!-- end of joint list -->
  <link name="arm_left_link_1_s">
    <visual>
      <origin rpy="0 0 0" xyz="0 0 0"/>
      <geometry>
        <mesh filename="package://motoman_sda10f_support/meshes/sda10f/visual/link_s.stl"/>
      </geometry>
      <material name="">
        <color rgba="0.12941176470588237 0.14901960784313725 0.7490196078431373 1.0"/>
      </material>
    </visual>
    <collision>
      <origin rpy="0 0 0" xyz="0 0 0"/>
      <geometry>
        <mesh filename="package://motoman_sda10f_support/meshes/sda10f/collision/link_s.stl"/>
      </geometry>
    </collision>
  </link>
  <link name="arm_left_link_2_l">
    <visual>
      <origin rpy="0 0 0" xyz="0 0 0"/>
      <geometry>
        <mesh filename="package://motoman_sda10f_support/meshes/sda10f/visual/link_l.stl"/>
      </geometry>
      <material name="">
        <color rgba="0.99 0.99 0.99 1"/>
      </material>
    </visual>
    <collision>
      <origin rpy="0 0 0" xyz="0 0 0"/>
      <geometry>
        <mesh filename="package://motoman_sda10f_support/meshes/sda10f/collision/link_l.stl"/>
      </geometry>
    </collision>
  </link>
  <link name="arm_left_link_3_e">
    <visual>
      <origin rpy="0 0 0" xyz="0 0 0"/>
      <geometry>
        <mesh filename="package://motoman_sda10f_support/meshes/sda10f/visual/link_e.stl"/>
      </geometry>
      <material name="">
        <color rgba="0.12941176470588237 0.14901960784313725 0.7490196078431373 1.0"/>
      </material>
    </visual>
    <collision>
      <origin rpy="0 0 0" xyz="0 0 0"/>
      <geometry>
        <mesh filename="package://motoman_sda10f_support/meshes/sda10f/collision/link_e.stl"/>
      </geometry>
    </collision>
  </link>
  <link name="arm_left_link_4_u">
    <visual>
      <origin rpy="0 0 0" xyz="0 0 0"/>
      <geometry>
        <mesh filename="package://motoman_sda10f_support/meshes/sda10f/visual/link_u.stl"/>
      </geometry>
      <material name="">
        <color rgba="0.99 0.99 0.99 1"/>
      </material>
    </visual>
    <collision>
      <origin rpy="0 0 0" xyz="0 0 0"/>
      <geometry>
        <mesh filename="package://motoman_sda10f_support/meshes/sda10f/collision/link_u.stl"/>
      </geometry>
    </collision>
  </link>
  <link name="arm_left_link_5_r">
    <visual>
      <origin rpy="0 0 0" xyz="0 0 0"/>
      <geometry>
        <mesh filename="package://motoman_sda10f_support/meshes/sda10f/visual/link_r.stl"/>
      </geometry>
      <material name="">
        <color rgba="0.12941176470588237 0.14901960784313725 0.7490196078431373 1.0"/>
      </material>
    </visual>
    <collision>
      <origin rpy="0 0 0" xyz="0 0 0"/>
      <geometry>
        <mesh filename="package://motoman_sda10f_support/meshes/sda10f/collision/link_r.stl"/>
      </geometry>
    </collision>
  </link>
  <link name="arm_left_link_6_b">
    <visual>
      <origin rpy="0 0 0" xyz="0 0 0"/>
      <geometry>
        <mesh filename="package://motoman_sda10f_support/meshes/sda10f/visual/link_b.stl"/>
      </geometry>
      <material name="">
        <color rgba="0.99 0.99 0.99 1"/>
      </material>
    </visual>
    <collision>
      <origin rpy="0 0 0" xyz="0 0 0"/>
      <geometry>
        <mesh filename="package://motoman_sda10f_support/meshes/sda10f/collision/link_b.stl"/>
      </geometry>
    </collision>
  </link>
  <link name="arm_left_link_7_t">
    <visual>
      <geometry>
        <mesh filename="package://motoman_sda10f_support/meshes/sda10f/visual/link_t.stl"/>
      </geometry>
      <material name="">
        <color rgba="0.12941176470588237 0.14901960784313725 0.7490196078431373 1.0"/>
      </material>
    </visual>
    <collision>
      <geometry>
        <mesh filename="package://motoman_sda10f_support/meshes/sda10f/collision/link_t.stl"/>
      </geometry>
    </collision>
  </link>
  <link name="arm_left_link_tool0"/>
  <joint name="arm_left_joint_1_s" type="revolute">
    <parent link="torso_link_b1"/>
    <child link="arm_left_link_1_s"/>
    <origin rpy="1.5707963267948966 0.0 0.0" xyz="0.100 0.265 0.0"/>
    <axis xyz="0 0 -1"/>
    <limit effort="0" lower="-3.141592653589793" upper="3.141592653589793" velocity="2.9670597283903604"/>
  </joint>
  <joint name="arm_left_joint_2_l" type="revolute">
    <parent link="arm_left_link_1_s"/>
    <child link="arm_left_link_2_l"/>
    <origin rpy="-1.5707963267948966 0.0 0.0" xyz="0.0 0.0 0.0"/>
    <axis xyz="0 0 -1"/>
    <limit effort="0" lower="-1.902408885" upper="1.9198621771937625" velocity="2.9670597283903604"/>
  </joint>
  <joint name="arm_left_joint_3_e" type="revolute">
    <parent link="arm_left_link_2_l"/>
    <child link="arm_left_link_3_e"/>
    <origin rpy="1.5707963267948966 0.0 0.0" xyz="0.0 0.360 0.0"/>
    <axis xyz="0 0 -1"/>
    <limit effort="0" lower="-2.9670597283903604" upper="2.9670597283903604" velocity="2.9670597283903604"/>
  </joint>
  <joint name="arm_left_joint_4_u" type="revolute">
    <parent link="arm_left_link_3_e"/>
    <child link="arm_left_link_4_u"/>
    <origin rpy="-1.5707963267948966 0.0 0.0" xyz="0.0 0.0 0.0"/>
    <axis xyz="0 0 1"/>
    <limit effort="0" lower="-2.356194490192345" upper="2.356194490192345" velocity="2.9670597283903604"/>
  </joint>
  <joint name="arm_left_joint_5_r" type="revolute">
    <parent link="arm_left_link_4_u"/>
    <child link="arm_left_link_5_r"/>
    <origin rpy="1.5707963267948966 0.0 0.0" xyz="0.0 0.360 0.0"/>
    <axis xyz="0 0 1"/>
    <limit effort="0" lower="-3.141592653589793" upper="3.141592653589793" velocity="3.490658503988659"/>
  </joint>
  <joint name="arm_left_joint_6_b" type="revolute">
    <parent link="arm_left_link_5_r"/>
    <child link="arm_left_link_6_b"/>
    <origin rpy="-1.5707963267948966 0.0 0.0" xyz="0.0 0.0 0.0"/>
    <axis xyz="0 0 1"/>
    <limit effort="0" lower="-1.9198621771937625" upper="1.9198621771937625" velocity="3.490658503988659"/>
  </joint>
  <joint name="arm_left_joint_7_t" type="revolute">
    <parent link="arm_left_link_6_b"/>
    <child link="arm_left_link_7_t"/>
    <origin rpy="-1.5707963267948966 0.0 0.0" xyz="0.0 0.155 0.0"/>
    <axis xyz="0 0 -1"/>
    <limit effort="0" lower="-3.141592653589793" upper="3.141592653589793" velocity="6.981317007977318"/>
  </joint>
  <joint name="arm_left_joint_tool0" type="fixed">
    <parent link="arm_left_link_7_t"/>
    <child link="arm_left_link_tool0"/>
    <origin rpy="0 0 3.141592653589793" xyz="0 0 0"/>
  </joint>
  <!-- end of joint list -->
  <link name="arm_right_link_1_s">
    <visual>
      <origin rpy="0 0 0" xyz="0 0 0"/>
      <geometry>
        <mesh filename="package://motoman_sda10f_support/meshes/sda10f/visual/link_s.stl"/>
      </geometry>
      <material name="">
        <color rgba="0.12941176470588237 0.14901960784313725 0.7490196078431373 1.0"/>
      </material>
    </visual>
    <collision>
      <origin rpy="0 0 0" xyz="0 0 0"/>
      <geometry>
        <mesh filename="package://motoman_sda10f_support/meshes/sda10f/collision/link_s.stl"/>
      </geometry>
    </collision>
  </link>
  <link name="arm_right_link_2_l">
    <visual>
      <origin rpy="0 0 0" xyz="0 0 0"/>
      <geometry>
        <mesh filename="package://motoman_sda10f_support/meshes/sda10f/visual/link_l.stl"/>
      </geometry>
      <material name="">
        <color rgba="0.99 0.99 0.99 1"/>
      </material>
    </visual>
    <collision>
      <origin rpy="0 0 0" xyz="0 0 0"/>
      <geometry>
        <mesh filename="package://motoman_sda10f_support/meshes/sda10f/collision/link_l.stl"/>
      </geometry>
    </collision>
  </link>
  <link name="arm_right_link_3_e">
    <visual>
      <origin rpy="0 0 0" xyz="0 0 0"/>
      <geometry>
        <mesh filename="package://motoman_sda10f_support/meshes/sda10f/visual/link_e.stl"/>
      </geometry>
      <material name="">
        <color rgba="0.12941176470588237 0.14901960784313725 0.7490196078431373 1.0"/>
      </material>
    </visual>
    <collision>
      <origin rpy="0 0 0" xyz="0 0 0"/>
      <geometry>
        <mesh filename="package://motoman_sda10f_support/meshes/sda10f/collision/link_e.stl"/>
      </geometry>
    </collision>
  </link>
  <link name="arm_right_link_4_u">
    <visual>
      <origin rpy="0 0 0" xyz="0 0 0"/>
      <geometry>
        <mesh filename="package://motoman_sda10f_support/meshes/sda10f/visual/link_u.stl"/>
      </geometry>
      <material name="">
        <color rgba="0.99 0.99 0.99 1"/>
      </material>
    </visual>
    <collision>
      <origin rpy="0 0 0" xyz="0 0 0"/>
      <geometry>
        <mesh filename="package://motoman_sda10f_support/meshes/sda10f/collision/link_u.stl"/>
      </geometry>
    </collision>
  </link>
  <link name="arm_right_link_5_r">
    <visual>
      <origin rpy="0 0 0" xyz="0 0 0"/>
      <geometry>
        <mesh filename="package://motoman_sda10f_support/meshes/sda10f/visual/link_r.stl"/>
      </geometry>
      <material name="">
        <color rgba="0.12941176470588237 0.14901960784313725 0.7490196078431373 1.0"/>
      </material>
    </visual>
    <collision>
      <origin rpy="0 0 0" xyz="0 0 0"/>
      <geometry>
        <mesh filename="package://motoman_sda10f_support/meshes/sda10f/collision/link_r.stl"/>
      </geometry>
    </collision>
  </link>
  <link name="arm_right_link_6_b">
    <visual>
      <origin rpy="0 0 0" xyz="0 0 0"/>
      <geometry>
        <mesh filename="package://motoman_sda10f_support/meshes/sda10f/visual/link_b.stl"/>
      </geometry>
      <material name="">
        <color rgba="0.99 0.99 0.99 1"/>
      </material>
    </visual>
    <collision>
      <origin rpy="0 0 0" xyz="0 0 0"/>
      <geometry>
        <mesh filename="package://motoman_sda10f_support/meshes/sda10f/collision/link_b.stl"/>
      </geometry>
    </collision>
  </link>
  <link name="arm_right_link_7_t">
    <visual>
      <geometry>
        <mesh filename="package://motoman_sda10f_support/meshes/sda10f/visual/link_t.stl"/>
      </geometry>
      <material name="">
        <color rgba="0.12941176470588237 0.14901960784313725 0.7490196078431373 1.0"/>
      </material>
    </visual>
    <collision>
      <geometry>
        <mesh filename="package://motoman_sda10f_support/meshes/sda10f/collision/link_t.stl"/>
      </geometry>
    </collision>
  </link>
  <link name="arm_right_link_tool0"/>
  <joint name="arm_right_joint_1_s" type="revolute">
    <parent link="torso_link_b1"/>
    <child link="arm_right_link_1_s"/>
    <origin rpy="1.5707963267948966 0.0 -3.141592653589793" xyz="0.100 -0.265 0.0"/>
    <axis xyz="0 0 1"/>
    <limit effort="0" lower="-3.141592653589793" upper="3.141592653589793" velocity="2.9670597283903604"/>
  </joint>
  <joint name="arm_right_joint_2_l" type="revolute">
    <parent link="arm_right_link_1_s"/>
    <child link="arm_right_link_2_l"/>
    <origin rpy="-1.5707963267948966 0.0 0.0" xyz="0.0 0.0 0.0"/>
    <axis xyz="0 0 1"/>
    <limit effort="0" lower="-1.902408885" upper="1.9198621771937625" velocity="2.9670597283903604"/>
  </joint>
  <joint name="arm_right_joint_3_e" type="revolute">
    <parent link="arm_right_link_2_l"/>
    <child link="arm_right_link_3_e"/>
    <origin rpy="1.5707963267948966 0.0 0.0" xyz="0.0 0.360 0.0"/>
    <axis xyz="0 0 1"/>
    <limit effort="0" lower="-2.9670597283903604" upper="2.9670597283903604" velocity="2.9670597283903604"/>
  </joint>
  <joint name="arm_right_joint_4_u" type="revolute">
    <parent link="arm_right_link_3_e"/>
    <child link="arm_right_link_4_u"/>
    <origin rpy="-1.5707963267948966 0.0 0.0" xyz="0.0 0.0 0.0"/>
    <axis xyz="0 0 -1"/>
    <limit effort="0" lower="-2.356194490192345" upper="2.356194490192345" velocity="2.9670597283903604"/>
  </joint>
  <joint name="arm_right_joint_5_r" type="revolute">
    <parent link="arm_right_link_4_u"/>
    <child link="arm_right_link_5_r"/>
    <origin rpy="1.5707963267948966 0.0 0.0" xyz="0.0 0.360 0.0"/>
    <axis xyz="0 0 -1"/>
    <limit effort="0" lower="-3.141592653589793" upper="3.141592653589793" velocity="3.490658503988659"/>
  </joint>
  <joint name="arm_right_joint_6_b" type="revolute">
    <parent link="arm_right_link_5_r"/>
    <child link="arm_right_link_6_b"/>
    <origin rpy="-1.5707963267948966 0.0 0.0" xyz="0.0 0.0 0.0"/>
    <axis xyz="0 0 -1"/>
    <limit effort="0" lower="-1.9198621771937625" upper="1.9198621771937625" velocity="3.490658503988659"/>
  </joint>
  <joint name="arm_right_joint_7_t" type="revolute">
    <parent link="arm_right_link_6_b"/>
    <child link="arm_right_link_7_t"/>
    <origin rpy="-1.5707963267948966 0.0 0.0" xyz="0.0 0.155 0.0"/>
    <axis xyz="0 0 1"/>
    <limit effort="0" lower="-3.141592653589793" upper="3.141592653589793" velocity="6.981317007977318"/>
  </joint>
  <joint name="arm_right_joint_tool0" type="fixed">
    <parent link="arm_right_link_7_t"/>
    <child link="arm_right_link_tool0"/>
    <origin rpy="0 0 3.141592653589793" xyz="0 0 0"/>
  </joint>
  <!-- end of joint list -->
  <!-- link list -->
  <link name="base_link"/>
  <!-- joint list -->
  <joint name="base_link_torso" type="fixed">
    <parent link="base_link"/>
    <child link="torso_base_link"/>
    <origin rpy="0 0 0" xyz="0 0 1.2"/>
  </joint>
  <!-- Create a fixed joint with a parameterized name. -->
  <joint name="milling_tool_joint" type="fixed">
    <!-- The parent link must be read from the robot model it is attached to. -->
    <parent link="arm_left_link_tool0"/>
    <child link="milling_tool"/>
    <!-- The tool is directly attached to the flange. -->
    <origin rpy="0 0 0" xyz="0 0 0"/>
  </joint>
  <link name="milling_tool">
    <visual>
      <geometry>
        <!-- The path to the visual meshes in the package. -->
        <mesh filename="package://motoman_sda10f_support/meshes/FDB340/SCHUNK.stl"/>
      </geometry>
    </visual>
    <collision>
      <geometry>
        <!-- The path to the collision meshes in the package. -->
        <mesh filename="package://motoman_sda10f_support/meshes/FDB340/SCHUNK.stl"/>
      </geometry>
    </collision>
  </link>
  <!-- TCP frame -->
  <joint name="tcp_joint" type="fixed">
    <origin rpy="0 0 0" xyz="0 0 0.116"/>
    <parent link="milling_tool"/>
    <child link="tcp"/>
  </joint>
  <link name="tcp"/>
  <!-- define the ur5's position and orientation in the world coordinate system -->
  <link name="world"/>
  <joint name="world_joint" type="fixed">
    <parent link="world"/>
    <child link="base_link"/>
    <!-- TODO: check base_link name of robot -->
    <origin rpy="0.0 0.0 0.0" xyz="0.0 0.0 0.0"/>
  </joint>
  
  
  <!--Create box in the right hand-->
  <joint name="sensor_joint" type="fixed">
    <!-- The parent link must be read from the robot model it is attached to. -->
    <parent link="arm_right_link_tool0"/>
    <child link="sensorbox"/>
    <!-- The tool is directly attached to the flange. -->
    <origin rpy="0 0 0" xyz="0 0 0.065"/>
  </joint>
  <link name="sensorbox">
    <visual>
      <geometry>
        <!-- The path to the visual meshes in the package. -->
        <box size="0.13 0.13 0.13"/>
      </geometry>
    </visual>
    <collision>
      <geometry>
        <!-- The path to the collision meshes in the package. -->
        <box size="0.13 0.13 0.13"/>
      </geometry>
    </collision>
  </link>
</robot>
